[2024-03-04 14:44:40,354] 96 werkzeug -WARNING  * Debugger is active!
[2024-03-04 14:44:40,364] 96 werkzeug -INFO  * Debugger PIN: 274-803-487
[2024-03-04 14:44:41,204] 96 werkzeug -INFO 127.0.0.1 - - [04/Mar/2024 14:44:41] "GET / HTTP/1.1" 200 -
[2024-03-04 14:44:41,998] 96 werkzeug -INFO 127.0.0.1 - - [04/Mar/2024 14:44:41] "GET /video HTTP/1.1" 200 -
[2024-03-04 14:45:32,072] 73 root -INFO Data Frame Gathered
[2024-03-04 14:45:32,123] 96 werkzeug -INFO 127.0.0.1 - - [04/Mar/2024 14:45:32] "[35m[1mPOST / HTTP/1.1[0m" 500 -
[2024-03-04 14:45:32,126] 96 werkzeug -ERROR Error on request:
Traceback (most recent call last):
  File "D:\DevOps\Project\BE Project\Outfit Recommendation\env\lib\site-packages\pandas\core\indexes\base.py", line 3653, in get_loc
    return self._engine.get_loc(casted_key)
  File "pandas\_libs\index.pyx", line 147, in pandas._libs.index.IndexEngine.get_loc
  File "pandas\_libs\index.pyx", line 176, in pandas._libs.index.IndexEngine.get_loc
  File "pandas\_libs\hashtable_class_helper.pxi", line 7080, in pandas._libs.hashtable.PyObjectHashTable.get_item
  File "pandas\_libs\hashtable_class_helper.pxi", line 7088, in pandas._libs.hashtable.PyObjectHashTable.get_item
KeyError: 0

The above exception was the direct cause of the following exception:

Traceback (most recent call last):
  File "D:\DevOps\Project\BE Project\Outfit Recommendation\env\lib\site-packages\werkzeug\debug\__init__.py", line 330, in debug_application
    app_iter = self.app(environ, start_response)
  File "D:\DevOps\Project\BE Project\Outfit Recommendation\env\lib\site-packages\flask-3.0.2-py3.8.egg\flask\app.py", line 1488, in __call__
    return self.wsgi_app(environ, start_response)
  File "D:\DevOps\Project\BE Project\Outfit Recommendation\env\lib\site-packages\flask-3.0.2-py3.8.egg\flask\app.py", line 1466, in wsgi_app
    response = self.handle_exception(e)
  File "D:\DevOps\Project\BE Project\Outfit Recommendation\env\lib\site-packages\flask-3.0.2-py3.8.egg\flask\app.py", line 1463, in wsgi_app
    response = self.full_dispatch_request()
  File "D:\DevOps\Project\BE Project\Outfit Recommendation\env\lib\site-packages\flask-3.0.2-py3.8.egg\flask\app.py", line 872, in full_dispatch_request
    rv = self.handle_user_exception(e)
  File "D:\DevOps\Project\BE Project\Outfit Recommendation\env\lib\site-packages\flask-3.0.2-py3.8.egg\flask\app.py", line 870, in full_dispatch_request
    rv = self.dispatch_request()
  File "D:\DevOps\Project\BE Project\Outfit Recommendation\env\lib\site-packages\flask-3.0.2-py3.8.egg\flask\app.py", line 855, in dispatch_request
    return self.ensure_sync(self.view_functions[rule.endpoint])(**view_args)  # type: ignore[no-any-return]
  File "d:\DevOps\Project\BE Project\Outfit Recommendation\app.py", line 110, in predict_datapoint
    gender = final_data[0]
  File "D:\DevOps\Project\BE Project\Outfit Recommendation\env\lib\site-packages\pandas\core\frame.py", line 3761, in __getitem__
    indexer = self.columns.get_loc(key)
  File "D:\DevOps\Project\BE Project\Outfit Recommendation\env\lib\site-packages\pandas\core\indexes\base.py", line 3655, in get_loc
    raise KeyError(key) from err
KeyError: 0

During handling of the above exception, another exception occurred:

Traceback (most recent call last):
  File "D:\DevOps\Project\BE Project\Outfit Recommendation\env\lib\site-packages\werkzeug\serving.py", line 362, in run_wsgi
    execute(self.server.app)
  File "D:\DevOps\Project\BE Project\Outfit Recommendation\env\lib\site-packages\werkzeug\serving.py", line 325, in execute
    for data in application_iter:
  File "D:\DevOps\Project\BE Project\Outfit Recommendation\env\lib\site-packages\werkzeug\debug\__init__.py", line 365, in debug_application
    environ["wsgi.errors"].write("".join(tb.render_traceback_text()))
OSError: [WinError 6] The handle is invalid
[2024-03-04 14:45:32,139] 96 werkzeug -INFO 127.0.0.1 - - [04/Mar/2024 14:45:32] "[36mGET /?__debugger__=yes&cmd=resource&f=style.css HTTP/1.1[0m" 304 -
[2024-03-04 14:45:32,143] 96 werkzeug -INFO 127.0.0.1 - - [04/Mar/2024 14:45:32] "[36mGET /?__debugger__=yes&cmd=resource&f=debugger.js HTTP/1.1[0m" 304 -
[2024-03-04 14:45:32,188] 96 werkzeug -INFO 127.0.0.1 - - [04/Mar/2024 14:45:32] "[36mGET /?__debugger__=yes&cmd=resource&f=console.png HTTP/1.1[0m" 304 -
[2024-03-04 14:45:32,230] 96 werkzeug -INFO 127.0.0.1 - - [04/Mar/2024 14:45:32] "[36mGET /?__debugger__=yes&cmd=resource&f=console.png HTTP/1.1[0m" 304 -
[2024-03-04 14:45:58,917] 96 werkzeug -INFO  * Detected change in 'd:\\DevOps\\Project\\BE Project\\Outfit Recommendation\\app.py', reloading
