[2024-03-05 11:04:04,651] 96 werkzeug -WARNING  * Debugger is active!
[2024-03-05 11:04:04,669] 96 werkzeug -INFO  * Debugger PIN: 111-650-926
[2024-03-05 11:04:21,995] 96 werkzeug -INFO 127.0.0.1 - - [05/Mar/2024 11:04:21] "GET / HTTP/1.1" 200 -
[2024-03-05 11:04:23,706] 96 werkzeug -INFO 127.0.0.1 - - [05/Mar/2024 11:04:23] "GET /video HTTP/1.1" 200 -
[2024-03-05 11:04:44,419] 73 root -INFO Data Frame Gathered
[2024-03-05 11:04:45,480] 96 werkzeug -INFO 127.0.0.1 - - [05/Mar/2024 11:04:45] "[35m[1mPOST / HTTP/1.1[0m" 500 -
[2024-03-05 11:04:45,488] 96 werkzeug -ERROR Error on request:
Traceback (most recent call last):
  File "d:\DevOps\Project\BE Project\Outfit Recommendation\env\lib\site-packages\werkzeug\debug\__init__.py", line 330, in debug_application
    app_iter = self.app(environ, start_response)
  File "d:\DevOps\Project\BE Project\Outfit Recommendation\env\lib\site-packages\flask-3.0.2-py3.8.egg\flask\app.py", line 1488, in __call__
    return self.wsgi_app(environ, start_response)
  File "d:\DevOps\Project\BE Project\Outfit Recommendation\env\lib\site-packages\flask-3.0.2-py3.8.egg\flask\app.py", line 1466, in wsgi_app
    response = self.handle_exception(e)
  File "d:\DevOps\Project\BE Project\Outfit Recommendation\env\lib\site-packages\flask-3.0.2-py3.8.egg\flask\app.py", line 1463, in wsgi_app
    response = self.full_dispatch_request()
  File "d:\DevOps\Project\BE Project\Outfit Recommendation\env\lib\site-packages\flask-3.0.2-py3.8.egg\flask\app.py", line 873, in full_dispatch_request
    return self.finalize_request(rv)
  File "d:\DevOps\Project\BE Project\Outfit Recommendation\env\lib\site-packages\flask-3.0.2-py3.8.egg\flask\app.py", line 892, in finalize_request
    response = self.make_response(rv)
  File "d:\DevOps\Project\BE Project\Outfit Recommendation\env\lib\site-packages\flask-3.0.2-py3.8.egg\flask\app.py", line 1164, in make_response
    raise TypeError(
TypeError: The view function for 'predict_datapoint' did not return a valid response. The function either returned None or ended without a return statement.

During handling of the above exception, another exception occurred:

Traceback (most recent call last):
  File "d:\DevOps\Project\BE Project\Outfit Recommendation\env\lib\site-packages\werkzeug\serving.py", line 362, in run_wsgi
    execute(self.server.app)
  File "d:\DevOps\Project\BE Project\Outfit Recommendation\env\lib\site-packages\werkzeug\serving.py", line 325, in execute
    for data in application_iter:
  File "d:\DevOps\Project\BE Project\Outfit Recommendation\env\lib\site-packages\werkzeug\debug\__init__.py", line 365, in debug_application
    environ["wsgi.errors"].write("".join(tb.render_traceback_text()))
OSError: [WinError 6] The handle is invalid
[2024-03-05 11:04:45,519] 96 werkzeug -INFO 127.0.0.1 - - [05/Mar/2024 11:04:45] "[36mGET /?__debugger__=yes&cmd=resource&f=style.css HTTP/1.1[0m" 304 -
[2024-03-05 11:04:45,525] 96 werkzeug -INFO 127.0.0.1 - - [05/Mar/2024 11:04:45] "[36mGET /?__debugger__=yes&cmd=resource&f=debugger.js HTTP/1.1[0m" 304 -
[2024-03-05 11:04:45,579] 96 werkzeug -INFO 127.0.0.1 - - [05/Mar/2024 11:04:45] "[36mGET /?__debugger__=yes&cmd=resource&f=console.png HTTP/1.1[0m" 304 -
[2024-03-05 11:04:45,612] 96 werkzeug -INFO 127.0.0.1 - - [05/Mar/2024 11:04:45] "[36mGET /?__debugger__=yes&cmd=resource&f=console.png HTTP/1.1[0m" 304 -
[2024-03-05 11:05:23,263] 96 werkzeug -INFO  * Detected change in 'D:\\DevOps\\Project\\BE Project\\Outfit Recommendation\\app.py', reloading
