[2024-03-05 10:34:54,709] 96 werkzeug -WARNING  * Debugger is active!
[2024-03-05 10:34:54,717] 96 werkzeug -INFO  * Debugger PIN: 111-650-926
[2024-03-05 10:34:55,412] 96 werkzeug -INFO 127.0.0.1 - - [05/Mar/2024 10:34:55] "GET / HTTP/1.1" 200 -
[2024-03-05 10:34:56,000] 96 werkzeug -INFO 127.0.0.1 - - [05/Mar/2024 10:34:56] "[35m[1mGET /video HTTP/1.1[0m" 500 -
[2024-03-05 10:34:56,043] 96 werkzeug -ERROR Error on request:
Traceback (most recent call last):
  File "d:\DevOps\Project\BE Project\Outfit Recommendation\env\lib\site-packages\werkzeug\debug\__init__.py", line 331, in debug_application
    yield from app_iter
  File "d:\DevOps\Project\BE Project\Outfit Recommendation\env\lib\site-packages\werkzeug\wsgi.py", line 256, in __next__
    return self._next()
  File "d:\DevOps\Project\BE Project\Outfit Recommendation\env\lib\site-packages\werkzeug\wrappers\response.py", line 32, in _iter_encoded
    for item in iterable:
  File "D:\DevOps\Project\BE Project\Outfit Recommendation\app.py", line 76, in generate_frames
    for idx, (measurement, value) in measurements:
ValueError: too many values to unpack (expected 2)

During handling of the above exception, another exception occurred:

Traceback (most recent call last):
  File "d:\DevOps\Project\BE Project\Outfit Recommendation\env\lib\site-packages\werkzeug\debug\__init__.py", line 353, in debug_application
    yield from response(environ, start_response)
  File "d:\DevOps\Project\BE Project\Outfit Recommendation\env\lib\site-packages\werkzeug\wrappers\response.py", line 579, in __call__
    start_response(status, headers)
  File "d:\DevOps\Project\BE Project\Outfit Recommendation\env\lib\site-packages\werkzeug\serving.py", line 317, in start_response
    raise AssertionError("Headers already set")
AssertionError: Headers already set

During handling of the above exception, another exception occurred:

Traceback (most recent call last):
  File "d:\DevOps\Project\BE Project\Outfit Recommendation\env\lib\site-packages\werkzeug\serving.py", line 362, in run_wsgi
    execute(self.server.app)
  File "d:\DevOps\Project\BE Project\Outfit Recommendation\env\lib\site-packages\werkzeug\serving.py", line 325, in execute
    for data in application_iter:
  File "d:\DevOps\Project\BE Project\Outfit Recommendation\env\lib\site-packages\werkzeug\debug\__init__.py", line 359, in debug_application
    environ["wsgi.errors"].write(
OSError: [WinError 6] The handle is invalid
[2024-03-05 10:34:59,853] 96 werkzeug -INFO 127.0.0.1 - - [05/Mar/2024 10:34:59] "GET / HTTP/1.1" 200 -
[2024-03-05 10:34:59,952] 96 werkzeug -INFO 127.0.0.1 - - [05/Mar/2024 10:34:59] "[35m[1mGET /video HTTP/1.1[0m" 500 -
[2024-03-05 10:34:59,958] 96 werkzeug -ERROR Error on request:
Traceback (most recent call last):
  File "d:\DevOps\Project\BE Project\Outfit Recommendation\env\lib\site-packages\werkzeug\debug\__init__.py", line 331, in debug_application
    yield from app_iter
  File "d:\DevOps\Project\BE Project\Outfit Recommendation\env\lib\site-packages\werkzeug\wsgi.py", line 256, in __next__
    return self._next()
  File "d:\DevOps\Project\BE Project\Outfit Recommendation\env\lib\site-packages\werkzeug\wrappers\response.py", line 32, in _iter_encoded
    for item in iterable:
  File "D:\DevOps\Project\BE Project\Outfit Recommendation\app.py", line 76, in generate_frames
    for idx, (measurement, value) in measurements:
ValueError: too many values to unpack (expected 2)

During handling of the above exception, another exception occurred:

Traceback (most recent call last):
  File "d:\DevOps\Project\BE Project\Outfit Recommendation\env\lib\site-packages\werkzeug\debug\__init__.py", line 353, in debug_application
    yield from response(environ, start_response)
  File "d:\DevOps\Project\BE Project\Outfit Recommendation\env\lib\site-packages\werkzeug\wrappers\response.py", line 579, in __call__
    start_response(status, headers)
  File "d:\DevOps\Project\BE Project\Outfit Recommendation\env\lib\site-packages\werkzeug\serving.py", line 317, in start_response
    raise AssertionError("Headers already set")
AssertionError: Headers already set

During handling of the above exception, another exception occurred:

Traceback (most recent call last):
  File "d:\DevOps\Project\BE Project\Outfit Recommendation\env\lib\site-packages\werkzeug\serving.py", line 362, in run_wsgi
    execute(self.server.app)
  File "d:\DevOps\Project\BE Project\Outfit Recommendation\env\lib\site-packages\werkzeug\serving.py", line 325, in execute
    for data in application_iter:
  File "d:\DevOps\Project\BE Project\Outfit Recommendation\env\lib\site-packages\werkzeug\debug\__init__.py", line 359, in debug_application
    environ["wsgi.errors"].write(
OSError: [WinError 6] The handle is invalid
[2024-03-05 10:35:03,339] 96 werkzeug -INFO 127.0.0.1 - - [05/Mar/2024 10:35:03] "GET / HTTP/1.1" 200 -
[2024-03-05 10:35:03,443] 96 werkzeug -INFO 127.0.0.1 - - [05/Mar/2024 10:35:03] "[35m[1mGET /video HTTP/1.1[0m" 500 -
[2024-03-05 10:35:03,447] 96 werkzeug -ERROR Error on request:
Traceback (most recent call last):
  File "d:\DevOps\Project\BE Project\Outfit Recommendation\env\lib\site-packages\werkzeug\debug\__init__.py", line 331, in debug_application
    yield from app_iter
  File "d:\DevOps\Project\BE Project\Outfit Recommendation\env\lib\site-packages\werkzeug\wsgi.py", line 256, in __next__
    return self._next()
  File "d:\DevOps\Project\BE Project\Outfit Recommendation\env\lib\site-packages\werkzeug\wrappers\response.py", line 32, in _iter_encoded
    for item in iterable:
  File "D:\DevOps\Project\BE Project\Outfit Recommendation\app.py", line 76, in generate_frames
    for idx, (measurement, value) in measurements:
ValueError: too many values to unpack (expected 2)

During handling of the above exception, another exception occurred:

Traceback (most recent call last):
  File "d:\DevOps\Project\BE Project\Outfit Recommendation\env\lib\site-packages\werkzeug\debug\__init__.py", line 353, in debug_application
    yield from response(environ, start_response)
  File "d:\DevOps\Project\BE Project\Outfit Recommendation\env\lib\site-packages\werkzeug\wrappers\response.py", line 579, in __call__
    start_response(status, headers)
  File "d:\DevOps\Project\BE Project\Outfit Recommendation\env\lib\site-packages\werkzeug\serving.py", line 317, in start_response
    raise AssertionError("Headers already set")
AssertionError: Headers already set

During handling of the above exception, another exception occurred:

Traceback (most recent call last):
  File "d:\DevOps\Project\BE Project\Outfit Recommendation\env\lib\site-packages\werkzeug\serving.py", line 362, in run_wsgi
    execute(self.server.app)
  File "d:\DevOps\Project\BE Project\Outfit Recommendation\env\lib\site-packages\werkzeug\serving.py", line 325, in execute
    for data in application_iter:
  File "d:\DevOps\Project\BE Project\Outfit Recommendation\env\lib\site-packages\werkzeug\debug\__init__.py", line 359, in debug_application
    environ["wsgi.errors"].write(
OSError: [WinError 6] The handle is invalid
[2024-03-05 10:35:11,245] 96 werkzeug -INFO 127.0.0.1 - - [05/Mar/2024 10:35:11] "GET / HTTP/1.1" 200 -
[2024-03-05 10:35:11,342] 96 werkzeug -INFO 127.0.0.1 - - [05/Mar/2024 10:35:11] "[35m[1mGET /video HTTP/1.1[0m" 500 -
[2024-03-05 10:35:11,343] 96 werkzeug -ERROR Error on request:
Traceback (most recent call last):
  File "d:\DevOps\Project\BE Project\Outfit Recommendation\env\lib\site-packages\werkzeug\debug\__init__.py", line 331, in debug_application
    yield from app_iter
  File "d:\DevOps\Project\BE Project\Outfit Recommendation\env\lib\site-packages\werkzeug\wsgi.py", line 256, in __next__
    return self._next()
  File "d:\DevOps\Project\BE Project\Outfit Recommendation\env\lib\site-packages\werkzeug\wrappers\response.py", line 32, in _iter_encoded
    for item in iterable:
  File "D:\DevOps\Project\BE Project\Outfit Recommendation\app.py", line 76, in generate_frames
    for idx, (measurement, value) in measurements:
ValueError: too many values to unpack (expected 2)

During handling of the above exception, another exception occurred:

Traceback (most recent call last):
  File "d:\DevOps\Project\BE Project\Outfit Recommendation\env\lib\site-packages\werkzeug\debug\__init__.py", line 353, in debug_application
    yield from response(environ, start_response)
  File "d:\DevOps\Project\BE Project\Outfit Recommendation\env\lib\site-packages\werkzeug\wrappers\response.py", line 579, in __call__
    start_response(status, headers)
  File "d:\DevOps\Project\BE Project\Outfit Recommendation\env\lib\site-packages\werkzeug\serving.py", line 317, in start_response
    raise AssertionError("Headers already set")
AssertionError: Headers already set

During handling of the above exception, another exception occurred:

Traceback (most recent call last):
  File "d:\DevOps\Project\BE Project\Outfit Recommendation\env\lib\site-packages\werkzeug\serving.py", line 362, in run_wsgi
    execute(self.server.app)
  File "d:\DevOps\Project\BE Project\Outfit Recommendation\env\lib\site-packages\werkzeug\serving.py", line 325, in execute
    for data in application_iter:
  File "d:\DevOps\Project\BE Project\Outfit Recommendation\env\lib\site-packages\werkzeug\debug\__init__.py", line 359, in debug_application
    environ["wsgi.errors"].write(
OSError: [WinError 6] The handle is invalid
[2024-03-05 10:35:11,944] 96 werkzeug -INFO 127.0.0.1 - - [05/Mar/2024 10:35:11] "GET / HTTP/1.1" 200 -
[2024-03-05 10:35:12,033] 96 werkzeug -INFO 127.0.0.1 - - [05/Mar/2024 10:35:12] "[35m[1mGET /video HTTP/1.1[0m" 500 -
[2024-03-05 10:35:12,048] 96 werkzeug -ERROR Error on request:
Traceback (most recent call last):
  File "d:\DevOps\Project\BE Project\Outfit Recommendation\env\lib\site-packages\werkzeug\debug\__init__.py", line 331, in debug_application
    yield from app_iter
  File "d:\DevOps\Project\BE Project\Outfit Recommendation\env\lib\site-packages\werkzeug\wsgi.py", line 256, in __next__
    return self._next()
  File "d:\DevOps\Project\BE Project\Outfit Recommendation\env\lib\site-packages\werkzeug\wrappers\response.py", line 32, in _iter_encoded
    for item in iterable:
  File "D:\DevOps\Project\BE Project\Outfit Recommendation\app.py", line 76, in generate_frames
    for idx, (measurement, value) in measurements:
ValueError: too many values to unpack (expected 2)

During handling of the above exception, another exception occurred:

Traceback (most recent call last):
  File "d:\DevOps\Project\BE Project\Outfit Recommendation\env\lib\site-packages\werkzeug\debug\__init__.py", line 353, in debug_application
    yield from response(environ, start_response)
  File "d:\DevOps\Project\BE Project\Outfit Recommendation\env\lib\site-packages\werkzeug\wrappers\response.py", line 579, in __call__
    start_response(status, headers)
  File "d:\DevOps\Project\BE Project\Outfit Recommendation\env\lib\site-packages\werkzeug\serving.py", line 317, in start_response
    raise AssertionError("Headers already set")
AssertionError: Headers already set

During handling of the above exception, another exception occurred:

Traceback (most recent call last):
  File "d:\DevOps\Project\BE Project\Outfit Recommendation\env\lib\site-packages\werkzeug\serving.py", line 362, in run_wsgi
    execute(self.server.app)
  File "d:\DevOps\Project\BE Project\Outfit Recommendation\env\lib\site-packages\werkzeug\serving.py", line 325, in execute
    for data in application_iter:
  File "d:\DevOps\Project\BE Project\Outfit Recommendation\env\lib\site-packages\werkzeug\debug\__init__.py", line 359, in debug_application
    environ["wsgi.errors"].write(
OSError: [WinError 6] The handle is invalid
[2024-03-05 10:35:12,083] 96 werkzeug -INFO 127.0.0.1 - - [05/Mar/2024 10:35:12] "GET / HTTP/1.1" 200 -
[2024-03-05 10:35:12,159] 96 werkzeug -INFO 127.0.0.1 - - [05/Mar/2024 10:35:12] "[35m[1mGET /video HTTP/1.1[0m" 500 -
[2024-03-05 10:35:12,159] 96 werkzeug -ERROR Error on request:
Traceback (most recent call last):
  File "d:\DevOps\Project\BE Project\Outfit Recommendation\env\lib\site-packages\werkzeug\debug\__init__.py", line 331, in debug_application
    yield from app_iter
  File "d:\DevOps\Project\BE Project\Outfit Recommendation\env\lib\site-packages\werkzeug\wsgi.py", line 256, in __next__
    return self._next()
  File "d:\DevOps\Project\BE Project\Outfit Recommendation\env\lib\site-packages\werkzeug\wrappers\response.py", line 32, in _iter_encoded
    for item in iterable:
  File "D:\DevOps\Project\BE Project\Outfit Recommendation\app.py", line 76, in generate_frames
    for idx, (measurement, value) in measurements:
ValueError: too many values to unpack (expected 2)

During handling of the above exception, another exception occurred:

Traceback (most recent call last):
  File "d:\DevOps\Project\BE Project\Outfit Recommendation\env\lib\site-packages\werkzeug\debug\__init__.py", line 353, in debug_application
    yield from response(environ, start_response)
  File "d:\DevOps\Project\BE Project\Outfit Recommendation\env\lib\site-packages\werkzeug\wrappers\response.py", line 579, in __call__
    start_response(status, headers)
  File "d:\DevOps\Project\BE Project\Outfit Recommendation\env\lib\site-packages\werkzeug\serving.py", line 317, in start_response
    raise AssertionError("Headers already set")
AssertionError: Headers already set

During handling of the above exception, another exception occurred:

Traceback (most recent call last):
  File "d:\DevOps\Project\BE Project\Outfit Recommendation\env\lib\site-packages\werkzeug\serving.py", line 362, in run_wsgi
    execute(self.server.app)
  File "d:\DevOps\Project\BE Project\Outfit Recommendation\env\lib\site-packages\werkzeug\serving.py", line 325, in execute
    for data in application_iter:
  File "d:\DevOps\Project\BE Project\Outfit Recommendation\env\lib\site-packages\werkzeug\debug\__init__.py", line 359, in debug_application
    environ["wsgi.errors"].write(
OSError: [WinError 6] The handle is invalid
[2024-03-05 10:35:12,351] 96 werkzeug -INFO 127.0.0.1 - - [05/Mar/2024 10:35:12] "GET / HTTP/1.1" 200 -
[2024-03-05 10:35:12,427] 96 werkzeug -INFO 127.0.0.1 - - [05/Mar/2024 10:35:12] "[35m[1mGET /video HTTP/1.1[0m" 500 -
[2024-03-05 10:35:12,429] 96 werkzeug -ERROR Error on request:
Traceback (most recent call last):
  File "d:\DevOps\Project\BE Project\Outfit Recommendation\env\lib\site-packages\werkzeug\debug\__init__.py", line 331, in debug_application
    yield from app_iter
  File "d:\DevOps\Project\BE Project\Outfit Recommendation\env\lib\site-packages\werkzeug\wsgi.py", line 256, in __next__
    return self._next()
  File "d:\DevOps\Project\BE Project\Outfit Recommendation\env\lib\site-packages\werkzeug\wrappers\response.py", line 32, in _iter_encoded
    for item in iterable:
  File "D:\DevOps\Project\BE Project\Outfit Recommendation\app.py", line 76, in generate_frames
    for idx, (measurement, value) in measurements:
ValueError: too many values to unpack (expected 2)

During handling of the above exception, another exception occurred:

Traceback (most recent call last):
  File "d:\DevOps\Project\BE Project\Outfit Recommendation\env\lib\site-packages\werkzeug\debug\__init__.py", line 353, in debug_application
    yield from response(environ, start_response)
  File "d:\DevOps\Project\BE Project\Outfit Recommendation\env\lib\site-packages\werkzeug\wrappers\response.py", line 579, in __call__
    start_response(status, headers)
  File "d:\DevOps\Project\BE Project\Outfit Recommendation\env\lib\site-packages\werkzeug\serving.py", line 317, in start_response
    raise AssertionError("Headers already set")
AssertionError: Headers already set

During handling of the above exception, another exception occurred:

Traceback (most recent call last):
  File "d:\DevOps\Project\BE Project\Outfit Recommendation\env\lib\site-packages\werkzeug\serving.py", line 362, in run_wsgi
    execute(self.server.app)
  File "d:\DevOps\Project\BE Project\Outfit Recommendation\env\lib\site-packages\werkzeug\serving.py", line 325, in execute
    for data in application_iter:
  File "d:\DevOps\Project\BE Project\Outfit Recommendation\env\lib\site-packages\werkzeug\debug\__init__.py", line 359, in debug_application
    environ["wsgi.errors"].write(
OSError: [WinError 6] The handle is invalid
[2024-03-05 10:35:12,603] 96 werkzeug -INFO 127.0.0.1 - - [05/Mar/2024 10:35:12] "GET / HTTP/1.1" 200 -
[2024-03-05 10:35:12,691] 96 werkzeug -INFO 127.0.0.1 - - [05/Mar/2024 10:35:12] "[35m[1mGET /video HTTP/1.1[0m" 500 -
[2024-03-05 10:35:12,691] 96 werkzeug -ERROR Error on request:
Traceback (most recent call last):
  File "d:\DevOps\Project\BE Project\Outfit Recommendation\env\lib\site-packages\werkzeug\debug\__init__.py", line 331, in debug_application
    yield from app_iter
  File "d:\DevOps\Project\BE Project\Outfit Recommendation\env\lib\site-packages\werkzeug\wsgi.py", line 256, in __next__
    return self._next()
  File "d:\DevOps\Project\BE Project\Outfit Recommendation\env\lib\site-packages\werkzeug\wrappers\response.py", line 32, in _iter_encoded
    for item in iterable:
  File "D:\DevOps\Project\BE Project\Outfit Recommendation\app.py", line 76, in generate_frames
    for idx, (measurement, value) in measurements:
ValueError: too many values to unpack (expected 2)

During handling of the above exception, another exception occurred:

Traceback (most recent call last):
  File "d:\DevOps\Project\BE Project\Outfit Recommendation\env\lib\site-packages\werkzeug\debug\__init__.py", line 353, in debug_application
    yield from response(environ, start_response)
  File "d:\DevOps\Project\BE Project\Outfit Recommendation\env\lib\site-packages\werkzeug\wrappers\response.py", line 579, in __call__
    start_response(status, headers)
  File "d:\DevOps\Project\BE Project\Outfit Recommendation\env\lib\site-packages\werkzeug\serving.py", line 317, in start_response
    raise AssertionError("Headers already set")
AssertionError: Headers already set

During handling of the above exception, another exception occurred:

Traceback (most recent call last):
  File "d:\DevOps\Project\BE Project\Outfit Recommendation\env\lib\site-packages\werkzeug\serving.py", line 362, in run_wsgi
    execute(self.server.app)
  File "d:\DevOps\Project\BE Project\Outfit Recommendation\env\lib\site-packages\werkzeug\serving.py", line 325, in execute
    for data in application_iter:
  File "d:\DevOps\Project\BE Project\Outfit Recommendation\env\lib\site-packages\werkzeug\debug\__init__.py", line 359, in debug_application
    environ["wsgi.errors"].write(
OSError: [WinError 6] The handle is invalid
[2024-03-05 10:35:12,819] 96 werkzeug -INFO 127.0.0.1 - - [05/Mar/2024 10:35:12] "GET / HTTP/1.1" 200 -
[2024-03-05 10:35:12,903] 96 werkzeug -INFO 127.0.0.1 - - [05/Mar/2024 10:35:12] "[35m[1mGET /video HTTP/1.1[0m" 500 -
[2024-03-05 10:35:12,909] 96 werkzeug -ERROR Error on request:
Traceback (most recent call last):
  File "d:\DevOps\Project\BE Project\Outfit Recommendation\env\lib\site-packages\werkzeug\debug\__init__.py", line 331, in debug_application
    yield from app_iter
  File "d:\DevOps\Project\BE Project\Outfit Recommendation\env\lib\site-packages\werkzeug\wsgi.py", line 256, in __next__
    return self._next()
  File "d:\DevOps\Project\BE Project\Outfit Recommendation\env\lib\site-packages\werkzeug\wrappers\response.py", line 32, in _iter_encoded
    for item in iterable:
  File "D:\DevOps\Project\BE Project\Outfit Recommendation\app.py", line 76, in generate_frames
    for idx, (measurement, value) in measurements:
ValueError: too many values to unpack (expected 2)

During handling of the above exception, another exception occurred:

Traceback (most recent call last):
  File "d:\DevOps\Project\BE Project\Outfit Recommendation\env\lib\site-packages\werkzeug\debug\__init__.py", line 353, in debug_application
    yield from response(environ, start_response)
  File "d:\DevOps\Project\BE Project\Outfit Recommendation\env\lib\site-packages\werkzeug\wrappers\response.py", line 579, in __call__
    start_response(status, headers)
  File "d:\DevOps\Project\BE Project\Outfit Recommendation\env\lib\site-packages\werkzeug\serving.py", line 317, in start_response
    raise AssertionError("Headers already set")
AssertionError: Headers already set

During handling of the above exception, another exception occurred:

Traceback (most recent call last):
  File "d:\DevOps\Project\BE Project\Outfit Recommendation\env\lib\site-packages\werkzeug\serving.py", line 362, in run_wsgi
    execute(self.server.app)
  File "d:\DevOps\Project\BE Project\Outfit Recommendation\env\lib\site-packages\werkzeug\serving.py", line 325, in execute
    for data in application_iter:
  File "d:\DevOps\Project\BE Project\Outfit Recommendation\env\lib\site-packages\werkzeug\debug\__init__.py", line 359, in debug_application
    environ["wsgi.errors"].write(
OSError: [WinError 6] The handle is invalid
[2024-03-05 10:35:15,558] 96 werkzeug -INFO 127.0.0.1 - - [05/Mar/2024 10:35:15] "GET / HTTP/1.1" 200 -
[2024-03-05 10:35:15,635] 96 werkzeug -INFO 127.0.0.1 - - [05/Mar/2024 10:35:15] "[35m[1mGET /video HTTP/1.1[0m" 500 -
[2024-03-05 10:35:15,639] 96 werkzeug -ERROR Error on request:
Traceback (most recent call last):
  File "d:\DevOps\Project\BE Project\Outfit Recommendation\env\lib\site-packages\werkzeug\debug\__init__.py", line 331, in debug_application
    yield from app_iter
  File "d:\DevOps\Project\BE Project\Outfit Recommendation\env\lib\site-packages\werkzeug\wsgi.py", line 256, in __next__
    return self._next()
  File "d:\DevOps\Project\BE Project\Outfit Recommendation\env\lib\site-packages\werkzeug\wrappers\response.py", line 32, in _iter_encoded
    for item in iterable:
  File "D:\DevOps\Project\BE Project\Outfit Recommendation\app.py", line 76, in generate_frames
    for idx, (measurement, value) in measurements:
ValueError: too many values to unpack (expected 2)

During handling of the above exception, another exception occurred:

Traceback (most recent call last):
  File "d:\DevOps\Project\BE Project\Outfit Recommendation\env\lib\site-packages\werkzeug\debug\__init__.py", line 353, in debug_application
    yield from response(environ, start_response)
  File "d:\DevOps\Project\BE Project\Outfit Recommendation\env\lib\site-packages\werkzeug\wrappers\response.py", line 579, in __call__
    start_response(status, headers)
  File "d:\DevOps\Project\BE Project\Outfit Recommendation\env\lib\site-packages\werkzeug\serving.py", line 317, in start_response
    raise AssertionError("Headers already set")
AssertionError: Headers already set

During handling of the above exception, another exception occurred:

Traceback (most recent call last):
  File "d:\DevOps\Project\BE Project\Outfit Recommendation\env\lib\site-packages\werkzeug\serving.py", line 362, in run_wsgi
    execute(self.server.app)
  File "d:\DevOps\Project\BE Project\Outfit Recommendation\env\lib\site-packages\werkzeug\serving.py", line 325, in execute
    for data in application_iter:
  File "d:\DevOps\Project\BE Project\Outfit Recommendation\env\lib\site-packages\werkzeug\debug\__init__.py", line 359, in debug_application
    environ["wsgi.errors"].write(
OSError: [WinError 6] The handle is invalid
